Workbook

Sheet September-2026
C1: Date: | F1: 46266 | K1: =F1 -> 46266
A2: SL | B2: Date | C2: Branch | D2: Member | F2: Actul Mem | G2: Lonee | I2: Actul Lonee | J2: This Month Savings Collection | K2: This Month Savings Return | L2: Savings | M2: Reguler Terget (Loan) | N2: Reguler Achiv (Loan) | O2: Exced Over Due Collection | Q2: Ad. Collection | R2: Over due De/Inc | S2: Monthly Installment | U2: DPS | W2: Today Disbument | Y2: Grant Total Disbument | Z2: Loan Outstanding | AA2: Overdue Outstanding | AB2: Recovary Rate | AC2: Cash in Hand | AD2: Bank
D3: Terget | E3: Achive | G3: Terget | H3: Achive | O3: Curent Due | P3: Ex Due | S3: Total | T3: Achive | U3: Ammount | V3: Taka
A4: 1 | B4: =$F$1 -> 46266 | C4: Lohagora | F4: 0 | I4: 0 | L4: 0 | T4: 0 | W4: 0 | Y4: =W4 -> 0 | Z4: 0 | AA4: 0 | AB4: 0 | AC4: 31 | AD4: 0
A5: 2 | B5: =$F$1 -> 46266 | C5: gobra | Y5: =W5
A6: 3 | B6: =$F$1 -> 46266 | C6: Mohajon | Y6: =W6
A7: 4 | B7: =$F$1 -> 46266 | C7: Noldi | F7: 872 | I7: 682 | L7: 15517475 | T7: 37 | Y7: =W7 | Z7: 51998307 | AA7: 2858154 | AB7: 87 | AC7: 30 | AD7: 298113
A8: 5 | B8: =$F$1 -> 46266 | C8: Narail | Y8: =W8
A9: Total | D9: =SUM(D4:D8) -> 0 | E9: =SUM(E4:E8) -> 0 | F9: =SUM(F4:F8) -> 872 | G9: =SUM(G4:G8) -> 0 | H9: =SUM(H4:H8) -> 0 | I9: =SUM(I4:I8) -> 682 | J9: =SUM(J4:J8) -> 0 | K9: =SUM(K4:K8) -> 0 | ... AD9: =SUM(AD4:AD8) -> 298113
C10: Date: | F10: =F1+1 -> 46267 | K10: =F10 -> 46267
A11: SL | B11: Date | C11: Branch | D11: Member | F11: Actul Mem | G11: Lonee | I11: Actul Lonee | J11: This Month Savings Collection | K11: This Month Savings Return | L11: Savings | M11: Reguler Terget (Loan) | N11: Reguler Achiv (Loan) | O11: Exced Over Due Collection | Q11: Ad. Collection | R11: Over due De/Inc | S11: Monthly Installment | U11: DPS | W11: Today Disbument | Y11: Grant Total Disbument | Z11: Loan Outstanding | AA11: Overdue Outstanding | AB11: Recovary Rate | AC11: Cash in Hand | AD11: Bank
D12: Terget | E12: Achive | G12: Terget | H12: Achive | O12: Curent Due | P12: Ex Due | S12: Total | T12: Achive | U12: Ammount | V12: Taka
A13: 1 | B13: =$F$10 -> 46267 | C13: Lohagora | Y13: =Y4+W13 -> 0
A14: 2 | B14: =$F$10 -> 46267 | C14: gobra | Y14: =Y5+W14 -> 0
A15: 3 | B15: =$F$10 -> 46267 | C15: Mohajon | W15: 600000 | Y15: =Y6+W15 -> 600000
A16: 4 | B16: =$F$10 -> 46267 | C16: Noldi | Y16: =Y7+W16 -> 0
A17: 5 | B17: =$F$10 -> 46267 | C17: Narail | Y17: =Y8+W17 -> 0
A18: Total | D18: =SUM(D13:D17) -> 0 | E18: =SUM(E13:E17) -> 0 | F18: =SUM(F13:F17) -> 0 | G18: =SUM(G13:G17) -> 0 | H18: =SUM(H13:H17) -> 0 | I18: =SUM(I13:I17) -> 0 | J18: =SUM(J13:J17) -> 0 | K18: =SUM(K13:K17) -> 0 | ... AD18: =SUM(AD13:AD17) -> 0
C19: Date: | F19: =F10+1 -> 46268 | K19: =F19 -> 46268
A20: SL | B20: Date | C20: Branch | D20: Member | F20: Actul Mem | G20: Lonee | I20: Actul Lonee | J20: This Month Savings Collection | K20: This Month Savings Return | L20: Savings | M20: Reguler Terget (Loan) | N20: Reguler Achiv (Loan) | O20: Exced Over Due Collection | Q20: Ad. Collection | R20: Over due De/Inc | S20: Monthly Installment | U20: DPS | W20: Today Disbument | Y20: Grant Total Disbument | Z20: Loan Outstanding | AA20: Overdue Outstanding | AB20: Recovary Rate | AC20: Cash in Hand | AD20: Bank | AE20: Bank
D21: Terget | E21: Achive | G21: Terget | H21: Achive | O21: Curent Due | P21: Ex Due | U21: Ammount | V21: Taka
A22: 1 | B22: =$F$19 -> 46268 | C22: Lohagora | F22: 783 | I22: 636 | L22: 19409061 | T22: 31 | W22: 230000 | Y22: =Y13+W22 -> 230000 | Z22: 53808716 | AA22: 2661956 | AB22: 90 | AC22: 0 | AD22: 323786
A23: 2 | B23: =$F$19 -> 46268 | C23: gobra | F23: 895 | I23: 740 | L23: 16277145 | T23: 19 | W23: 420000 | Y23: =Y14+W23 -> 420000 | Z23: 52138099 | AA23: 2507070 | AB23: 96 | AC23: 221 | AD23: 507664
A24: 3 | B24: =$F$19 -> 46268 | C24: Mohajon | F24: 915 | I24: 757 | L24: 22818474 | T24: 86 | W24: 550000 | Y24: =Y15+W24 -> 1150000 | Z24: 67778747 | AA24: 27703640 | AB24: 83 | AC24: 156 | AD24: 595323
A25: 4 | B25: =$F$19 -> 46268 | C25: Noldi | F25: 872 | I25: 682 | L25: 15517475 | T25: 37 | W25: 700000 | Y25: =Y16+W25 -> 700000 | Z25: 51998307 | AA25: 2858154 | AB25: 87 | AC25: 30 | AD25: 298113
A26: 5 | B26: =$F$19 -> 46268 | C26: Narail | F26: 862 | I26: 698 | L26: 17352854 | T26: 28 | W26: 540000 | Y26: =Y17+W26 -> 540000 | Z26: 60693393 | AA26: 2867549 | AB26: 100 | AC26: 25 | AD26: 472888
A27: Total | D27: =SUM(D22:D26) -> 0 | E27: =SUM(E22:E26) -> 0 | F27: =SUM(F22:F26) -> 4327 | G27: =SUM(G22:G26) -> 0 | H27: =SUM(H22:H26) -> 0 | I27: =SUM(I22:I26) -> 3513 | J27: =SUM(J22:J26) -> 0 | K27: =SUM(K22:K26) -> 0 | ... AD27: =SUM(AD22:AD26) -> 2197774
C28: Date: | F28: =F19+3 -> 46271 | K28: =F28 -> 46271
A29: SL | B29: Date | C29: Branch | D29: Member | F29: Actul Mem | G29: Lonee | I29: Actul Lonee | J29: This Month Savings Collection | K29: This Month Savings Return | L29: Savings | M29: Reguler Terget (Loan) | N29: Reguler Achiv (Loan) | O29: Exced Over Due Collection | Q29: Ad. Collection | R29: Over due De/Inc | S29: Monthly Installment | U29: DPS | W29: Today Disbument | Y29: Grant Total Disbument | Z29: Loan Outstanding | AA29: Overdue Outstanding | AB29: Recovary Rate | AC29: Cash in Hand | AD29: Bank
D30: Terget | E30: Achive | G30: Terget | H30: Achive | O30: Curent Due | P30: Ex Due | S30: Total | T30: Achive | U30: Ammount | V30: Taka
A31: 1 | B31: =$F$28 -> 46271 | C31: Lohagora | F31: 782 | I31: 638 | L31: 19421642 | T31: 50 | W31: 190000 | Y31: =Y22+W31 -> 420000 | Z31: 53830567 | AA31: 2853340 | AB31: 86 | AC31: 11212 | AD31: 326817
A32: 2 | B32: =$F$28 -> 46271 | C32: gobra | F32: 896 | I32: 740 | L32: 16054714 | T32: 43 | W32: 0 | Y32: =Y23+W32 -> 420000 | Z32: 51866437 | AA32: 2609685 | AB32: 96 | AC32: 223 | AD32: 462063
A33: 3 | B33: =$F$28 -> 46271 | C33: Mohajon | D33: 2 | E33: -2 | F33: 916 | I33: 755 | L33: 22867108 | T33: 152 | W33: 50000 | Y33: =Y24+W33 -> 1200000 | Z33: 67159771 | AA33: 2999963 | AB33: 89 | AC33: 210 | AD33: 1369129
A34: 4 | B34: =$F$28 -> 46271 | C34: Noldi | F34: 871 | I34: 679 | L34: 15404460 | T34: 63 | W34: 0 | Y34: =Y25+W34 -> 700000 | Z34: 51732879 | AA34: 2880866 | AB34: 100 | AC34: 60 | AD34: 423501
A35: 6 | B35: =$F$28 -> 46271 | C35: Narail | F35: 860 | I35: 693 | L35: 17254606 | T35: 45 | W35: 0 | Y35: =Y26+W35 -> 540000 | Z35: 60236746 | AA35: 2963751 | AB35: 100 | AC35: 20 | AD35: 886238
A36: Total | D36: =SUM(D31:D35) -> 2 | E36: =SUM(E31:E35) -> -2 | F36: =SUM(F31:F35) -> 4325 | G36: =SUM(G31:G35) -> 0 | H36: =SUM(H31:H35) -> 0 | I36: =SUM(I31:I35) -> 3505 | J36: =SUM(J31:J35) -> 0 | K36: =SUM(K31:K35) -> 0 | ... AD36: =SUM(AD31:AD35) -> 3467748
C37: Date: | F37: =F28+1 -> 46272 | K37: =F37 -> 46272
A38: SL | B38: Date | C38: Branch | D38: Member | F38: Actul Mem | G38: Lonee | I38: Actul Lonee | J38: This Month Savings Collection | K38: This Month Savings Return | L38: Savings | M38: Reguler Terget (Loan) | N38: Reguler Achiv (Loan) | O38: Exced Over Due Collection | Q38: Ad. Collection | R38: Over due De/Inc | S38: Total Monthly Collection | U38: DPS | W38: Today Disbument | Y38: Grant Total Disbument | Z38: Loan Outstanding | AA38: Overdue Outstanding | AB38: Recovary Rate | AC38: Cash in Hand | AD38: Bank
D39: Terget | E39: Achive | G39: Terget | H39: Achive | O39: Curent Due | P39: Ex Due | U39: Ammount | V39: Taka
A40: 1 | B40: =$F$37 -> 46272 | C40: Lohagora | F40: 780 | I40: 635 | L40: 19469994 | T40: 86 | W40: 50000 | Y40: =Y31+W40 -> 470000 | Z40: 53491829 | AA40: 2991094 | AB40: 89 | AC40: 10 | AD40: 760822
...

Sheet Compare Sep-26
B1: Bandhu Kallyan Foundation
B2: Narail Area
B3: Month-August-26 | E3: Day | F3: =C6 -> 46293
F4: =IFERROR(__xludf.DUMMYFUNCTION("AI(""Fill an appropriate value for this cell based on the table context"")"),"Loanee") -> Loanee | G4: =IFERROR(__xludf.DUMMYFUNCTION("AI(""Fill an appropriate value for this cell based on the table context"")"),"") | Q4: Date:- | S4: =C6 -> 46293
A5: Branch | B5: Member | D5: Inc / Dec | E5: Loanee | G5: Inc / Dec | H5: Savings | J5: Inc / Dec | K5: Outstading | M5: Diferent | N5: O.T.R | O5: Dis | P5: Monthly | R5: Due | S5: overdue | U5: Inc / Dec | V5: Cash In Hand | W5: BANK | X5: Monthly Kisti Aday ( % ) | Y5: Weekly Loney
B6: 46234 | C6: 46293 | E6: =B6 -> 46234 | F6: =C6 -> 46293 | H6: =E6 -> 46234 | I6: =F6 -> 46293 | K6: =H6 -> 46234 | L6: =I6 -> 46293 | P6: Total | Q6: Aday | S6: Up To | T6: This Month
A7: Narail | B7: 858 | C7: =SUMIFS('September-2026'!F:F,'September-2026'!$B:$B,$C$6,'September-2026'!$C:$C,$A:$A) -> 863 | D7: =C7-B7 -> 5 | E7: 705 | F7: =SUMIFS('September-2026'!I:I,'September-2026'!$B:$B,$C$6,'September-2026'!$C:$C,$A:$A) -> 700 | G7: =F7-E7 -> -5 | H7: 17448810 | I7: =SUMIFS('September-2026'!L:L,'September-2026'!$B:$B,$C$6,'September-2026'!$C:$C,$A:$A) -> 17598499 | J7: =I7-H7 -> 149689 | K7: 60666312 | L7: =SUMIFS('September-2026'!Z:Z,'September-2026'!$B:$B,$C$6,'September-2026'!$C:$C,$A:$A) -> 61450252 | M7: =L7-K7 -> 783940 | N7: =SUMIFS('September-2026'!AB:AB,'September-2026'!$B:$B,$C$6,'September-2026'!$C:$C,$A:$A) -> 93 | O7: =SUMIFS('September-2026'!Y:Y,'September-2026'!$B:$B,$C$6,'September-2026'!$C:$C,$A:$A) -> 7015000 | P7: 527 | Q7: =SUMIFS('September-2026'!T:T,'September-2026'!$B:$B,$C$6,'September-2026'!$C:$C,$A:$A) -> 491 | R7: =P7-Q7 -> 36 | S7: 2770418 | T7: =SUMIFS('September-2026'!AA:AA,'September-2026'!$B:$B,$C$6,'September-2026'!$C:$C,$A:$A) -> 3237365 | U7: =T7-S7 -> 466947 | V7: =SUMIFS('September-2026'!AC:AC,'September-2026'!$B:$B,$C$6,'September-2026'!$C:$C,$A:$A) -> 217 | W7: =SUMIFS('September-2026'!AD:AD,'September-2026'!$B:$B,$C$6,'September-2026'!$C:$C,$A:$A) -> 2457030 | X7: =Q7/P7 -> 0.9316888 | Y7: 90
A8: Noldi | B8: 873 | C8: =SUMIFS('September-2026'!F:F,'September-2026'!$B:$B,$C$6,'September-2026'!$C:$C,$A:$A) -> 885 | D8: =C8-B8 -> 12 | E8: 686 | F8: =SUMIFS('September-2026'!I:I,'September-2026'!$B:$B,$C$6,'September-2026'!$C:$C,$A:$A) -> 693 | G8: =F8-E8 -> 7 | H8: 15480081 | I8: =SUMIFS('September-2026'!L:L,'September-2026'!$B:$B,$C$6,'September-2026'!$C:$C,$A:$A) -> 15836369 | J8: =I8-H8 -> 356288 | K8: 51742527 | L8: =SUMIFS('September-2026'!Z:Z,'September-2026'!$B:$B,$C$6,'September-2026'!$C:$C,$A:$A) -> 52762619 | M8: =L8-K8 -> 1020092 | N8: =SUMIFS('September-2026'!AB:AB,'September-2026'!$B:$B,$C$6,'September-2026'!$C:$C,$A:$A) -> 100 | O8: =SUMIFS('September-2026'!Y:Y,'September-2026'!$B:$B,$C$6,'September-2026'!$C:$C,$A:$A) -> 7590000 | P8: 525 | Q8: =SUMIFS('September-2026'!T:T,'September-2026'!$B:$B,$C$6,'September-2026'!$C:$C,$A:$A) -> 512 | R8: =P8-Q8 -> 13 | S8: 2838342 | T8: =SUMIFS('September-2026'!AA:AA,'September-2026'!$B:$B,$C$6,'September-2026'!$C:$C,$A:$A) -> 2984488 | U8: =T8-S8 -> 146146 | V8: =SUMIFS('September-2026'!AC:AC,'September-2026'!$B:$B,$C$6,'September-2026'!$C:$C,$A:$A) -> 14913 | W8: =SUMIFS('September-2026'!AD:AD,'September-2026'!$B:$B,$C$6,'September-2026'!$C:$C,$A:$A) -> 2040794 | X8: =Q8/P8 -> 0.9752381 | Y8: =E8-P8 -> 161
A9: Lohagora | B9: 780 | C9: =SUMIFS('September-2026'!F:F,'September-2026'!$B:$B,$C$6,'September-2026'!$C:$C,$A:$A) -> 777 | D9: =C9-B9 -> -3 | E9: 640 | F9: =SUMIFS('September-2026'!I:I,'September-2026'!$B:$B,$C$6,'September-2026'!$C:$C,$A:$A) -> 635 | G9: =F9-E9 -> -5 | H9: 19409733 | I9: =SUMIFS('September-2026'!L:L,'September-2026'!$B:$B,$C$6,'September-2026'!$C:$C,$A:$A) -> 19731838 | J9: =I9-H9 -> 322105 | K9: 53930160 | L9: =SUMIFS('September-2026'!Z:Z,'September-2026'!$B:$B,$C$6,'September-2026'!$C:$C,$A:$A) -> 55093843 | M9: =L9-K9 -> 1163683 | N9: =SUMIFS('September-2026'!AB:AB,'September-2026'!$B:$B,$C$6,'September-2026'!$C:$C,$A:$A) -> 97 | O9: =SUMIFS('September-2026'!Y:Y,'September-2026'!$B:$B,$C$6,'September-2026'!$C:$C,$A:$A) -> 7520000 | P9: 532 | Q9: =SUMIFS('September-2026'!T:T,'September-2026'!$B:$B,$C$6,'September-2026'!$C:$C,$A:$A) -> 514 | R9: =P9-Q9 -> 18 | S9: 2632579 | T9: =SUMIFS('September-2026'!AA:AA,'September-2026'!$B:$B,$C$6,'September-2026'!$C:$C,$A:$A) -> 2833149 | U9: =T9-S9 -> 200570 | V9: =SUMIFS('September-2026'!AC:AC,'September-2026'!$B:$B,$C$6,'September-2026'!$C:$C,$A:$A) -> 342 | W9: =SUMIFS('September-2026'!AD:AD,'September-2026'!$B:$B,$C$6,'September-2026'!$C:$C,$A:$A) -> 3230019 | X9: =Q9/P9 -> 0.96616541 | Y9: =E9-P9 -> 108
A10: Mohajon | B10: 913 | C10: =SUMIFS('September-2026'!F:F,'September-2026'!$B:$B,$C$6,'September-2026'!$C:$C,$A:$A) -> 913 | D10: =C10-B10 -> 0 | E10: 765 | F10: =SUMIFS('September-2026'!I:I,'September-2026'!$B:$B,$C$6,'September-2026'!$C:$C,$A:$A) -> 767 | G10: =F10-E10 -> 2 | H10: 22755262 | I10: =SUMIFS('September-2026'!L:L,'September-2026'!$B:$B,$C$6,'September-2026'!$C:$C,$A:$A) -> 23139576 | J10: =I10-H10 -> 384314 | K10: 67533066 | L10: =SUMIFS('September-2026'!Z:Z,'September-2026'!$B:$B,$C$6,'September-2026'!$C:$C,$A:$A) -> 68860455 | M10: =L10-K10 -> 1327389 | N10: =SUMIFS('September-2026'!AB:AB,'September-2026'!$B:$B,$C$6,'September-2026'!$C:$C,$A:$A) -> 93 | O10: =SUMIFS('September-2026'!Y:Y,'September-2026'!$B:$B,$C$6,'September-2026'!$C:$C,$A:$A) -> 9286000 | P10: 675 | Q10: =SUMIFS('September-2026'!T:T,'September-2026'!$B:$B,$C$6,'September-2026'!$C:$C,$A:$A) -> 638 | R10: =P10-Q10 -> 37 | S10: 2599812 | T10: =SUMIFS('September-2026'!AA:AA,'September-2026'!$B:$B,$C$6,'September-2026'!$C:$C,$A:$A) -> 3135352 | U10: =T10-S10 -> 535540 | V10: =SUMIFS('September-2026'!AC:AC,'September-2026'!$B:$B,$C$6,'September-2026'!$C:$C,$A:$A) -> 2900 | W10: =SUMIFS('September-2026'!AD:AD,'September-2026'!$B:$B,$C$6,'September-2026'!$C:$C,$A:$A) -> 4047368 | X10: =Q10/P10 -> 0.94518519 | Y10: =E10-P10 -> 90
A11: Gobra | B11: 897 | C11: =SUMIFS('September-2026'!F:F,'September-2026'!$B:$B,$C$6,'September-2026'!$C:$C,$A:$A) -> 910 | D11: =C11-B11 -> 13 | E11: 741 | F11: =SUMIFS('September-2026'!I:I,'September-2026'!$B:$B,$C$6,'September-2026'!$C:$C,$A:$A) -> 746 | G11: =F11-E11 -> 5 | H11: 16266960 | I11: =SUMIFS('September-2026'!L:L,'September-2026'!$B:$B,$C$6,'September-2026'!$C:$C,$A:$A) -> 16407489 | J11: =I11-H11 -> 140529 | K11: 51988891 | L11: =SUMIFS('September-2026'!Z:Z,'September-2026'!$B:$B,$C$6,'September-2026'!$C:$C,$A:$A) -> 52562754 | M11: =L11-K11 -> 573863 | N11: =SUMIFS('September-2026'!AB:AB,'September-2026'!$B:$B,$C$6,'September-2026'!$C:$C,$A:$A) -> 96 | O11: =SUMIFS('September-2026'!Y:Y,'September-2026'!$B:$B,$C$6,'September-2026'!$C:$C,$A:$A) -> 5753000 | P11: 473 | Q11: =SUMIFS('September-2026'!T:T,'September-2026'!$B:$B,$C$6,'September-2026'!$C:$C,$A:$A) -> 424 | R11: =P11-Q11 -> 49 | S11: 2473437 | T11: =SUMIFS('September-2026'!AA:AA,'September-2026'!$B:$B,$C$6,'September-2026'!$C:$C,$A:$A) -> 3140817 | U11: =T11-S11 -> 667380 | V11: =SUMIFS('September-2026'!AC:AC,'September-2026'!$B:$B,$C$6,'September-2026'!$C:$C,$A:$A) -> 776 | W11: =SUMIFS('September-2026'!AD:AD,'September-2026'!$B:$B,$C$6,'September-2026'!$C:$C,$A:$A) -> 3051193 | X11: =Q11/P11 -> 0.89640592 | Y11: =E11-P11 -> 268
A12: Total | B12: =SUM(B7:B11) -> 4321 | C12: =SUM(C7:C11) -> 4348 | D12: =SUM(D7:D11) -> 27 | E12: =SUM(E7:E11) -> 3537 | F12: =SUM(F7:F11) -> 3541 | G12: =SUM(G7:G11) -> 4 | H12: =SUM(H7:H11) -> 91360846 | I12: =SUM(I7:I11) -> 92713771 | ... M12: =SUM(M7:M11) -> 4868967 | N12: =AVERAGE(N7:N11) -> 95.8 | O12: =SUM(O7:O11) -> 37164000 | P12: =SUM(P7:P11) -> 2732 | Q12: =SUM(Q7:Q11) -> 2579 | R12: =SUM(R7:R11) -> 153 | S12: =SUM(S7:S11) -> 13314588 | T12: =SUM(T7:T11) -> 15331171 | U12: =SUM(U7:U11) -> 2016583 | V12: =SUM(V7:V11) -> 19148 | W12: =SUM(W7:W11) -> 14826404 | X12: =AVERAGE(X7:X11) -> 0.94293668 | Y12: =SUM(Y7:Y11) -> 717

Sheet Month Closing-sep-26
C1: বন্ধু কল্যাণ ফাউন্ডেশন
C2: শাখা ভিত্তিক মাসিক অর্জন সিট
C3: মাসের নাম- আগষ্ট-২০২৬ | M3: নড়াইল এরিয়া | AA3: ZvwiL =30/12/25
A4: ক্র নং | B4: শাখার নাম | C4: সমিতি | D4: সদস্য | F4: ঋণী | H4: সঞ্চয় স্থিতি | J4: ঋণ স্থিতি | L4: সাধারণ বকেয়া | N4: OTR | P4: হ্রাস /বৃদ্ধি | Q4: হাতে নগদ | R4: ব্যাংক | S4: লাভ/ক্ষতি | V4: বিতরণ- আগষ্ট-২৬
D5: হ্রাস /বৃদ্ধি | E5: মোট | F5: হ্রাস /বৃদ্ধি | G5: মোট | H5: হ্রাস /বৃদ্ধি | I5: মোট | J5: হ্রাস /বৃদ্ধি | K5: মোট | L5: হ্রাস /বৃদ্ধি | M5: মোট | N5: বিগত মাস | O5: এ মাস | S5: এ মাসে | T5: এ বছর | U5: এ যাবৎ | V5: সংখ্যা | W5: টাকা
A6: 1 | B6: নড়াইল সদর | C6: 57 | D6: 15 | E6: 858 | F6: 5 | G6: 705 | H6: 342499 | I6: 17448810 | J6: -90475 | K6: 60666312 | L6: 36772 | M6: 2770418 | N6: 98.773145 | O6: 98.92 | P6: =O6-N6 -> 0.14685454 | Q6: 60300 | R6: 450218 | S6: -86419 | T6: -35645 | U6: 3260735 | V6: 43 | W6: 6430000
A7: 2 | B7: নলদী | C7: 63 | D7: 7 | E7: 873 | F7: -5 | G7: 686 | H7: 305552 | I7: 15480081 | J7: 531913 | K7: 51742527 | L7: -6005 | M7: 2838342 | N7: 99.660884 | O7: =IFERROR(I17/H17%, 0) -> 99.380119 | P7: =O7-N7 -> -0.28076483 | Q7: 22310 | R7: 122923 | S7: 100929 | T7: 301241 | U7: 9212964 | V7: 35 | W7: 6450000
A8: 3 | B8: লোহাগড়া | C8: 68 | D8: 7 | E8: 780 | F8: -1 | G8: 640 | H8: 378324 | I8: 19409733 | J8: 285393 | K8: 53930160 | L8: 19948 | M8: 2632579 | N8: 99.109116 | O8: 99.19 | P8: =O8-N8 -> 0.080883519 | Q8: 36500 | R8: 110301 | S8: 161853 | T8: 472170 | U8: 10861662 | V8: 44 | W8: 6570000
A9: 4 | B9: মহাজন | C9: 60 | D9: 13 | E9: 913 | F9: 3 | G9: 765 | H9: 410331 | I9: 22755262 | J9: -642522 | K9: 67533066 | L9: 36038 | M9: 2599812 | N9: 99.008256 | O9: =IFERROR(I19/H19%, 0) -> 98.892343 | P9: =O9-N9 -> -0.11591334 | Q9: 28056 | R9: 629117 | S9: 219338 | T9: 481712 | U9: 4638415 | V9: 55 | W9: 7645000
A10: 5 | B10: গোবরা | C10: 72 | D10: 4 | E10: 897 | F10: -6 | G10: 741 | H10: 289524 | I10: 16266960 | J10: 504518 | K10: 51988891 | L10: -5618 | M10: 2473437 | N10: 99.404153 | O10: =IFERROR(I20/H20%, 0) -> 99.400015 | P10: =O10-N10 -> -0.0041383678 | Q10: 49024 | R10: 856425 | S10: 163803 | T10: 448978 | U10: 17279883 | V10: 43 | W10: 6280000
B11: মোট | C11: =SUM(C6:C10) -> 320 | D11: =SUM(D6:D10) -> 46 | E11: =SUM(E6:E10) -> 4321 | F11: =SUM(F6:F10) -> -4 | G11: =SUM(G6:G10) -> 3537 | H11: =SUM(H6:H10) -> 1726230 | I11: =SUM(I6:I10) -> 91360846 | J11: =SUM(J6:J10) -> 588827 | ... M11: =SUM(M6:M10) -> 13314588 | N11: =AVERAGE(N6:N10) -> 99.191111 | O11: =AVERAGE(O6:O10) -> 99.156495 | P11: =O11-N11 -> -0.034615696 | Q11: =SUM(Q6:Q10) -> 196190 | R11: =SUM(R6:R10) -> 2168984 | S11: =SUM(S6:S10) -> 559504 | T11: =SUM(T6:T10) -> 1668456 | U11: =SUM(U6:U10) -> 45253659 | V11: =SUM(V6:V10) -> 220 | W11: =SUM(W6:W10) -> 33375000
C12: হলুদ চিহ্নিত ঘরে সূত্র দেওয়া। হলুদ ঘরে লেখা যাবে না ।
B14: শাখা | C14: সংখ্যা | D14: সঞ্চয় লভ্যাংশ | E14: মাসিক কিস্তির সংখ্যা | G14: শাখা | H14: আদায়যোগ্য | I14: আদায়কৃত | J14: OTR | K14: বিগত পার | L14: এ মাসে পার | M14: রাইট অফ আদায় | N14: বকেয়া গত মাস | O14: বকেয়া এ মাস | P14: হ্রাস /বৃদ্ধি | Q14: LLP | R14: চলতি বকেয়া | T14: হ্রাস /বৃদ্ধি | U14: এ মাসে নতুন
R15: গত মাস | S15: বর্তমান মাস
B16: নড়াইল সদর | G16: নড়াইল সদর | H16: 6487575 | I16: 6418086 | J16: =IFERROR(I16/H16%, 0) -> 98.928891 | K16: 0.0587 | L16: 0.0571 | M16: 516 | N16: 91 | O16: 89 | P16: =O16-N16 -> -2 | R16: 12 | S16: 12 | T16: =S16-R16 -> 0 | U16: 0
B17: নলদী | G17: নলদী | H17: 5869031 | I17: 5832650 | J17: =IFERROR(I17/H17%, 0) -> 99.380119 | K17: 0.0591 | L17: 0.0611 | M17: 50 | N17: 141 | O17: 143 | P17: =O17-N17 -> 2 | R17: 4 | S17: 4 | T17: =S17-R17 -> 0 | U17: 2
B18: লোহাগড়া | G18: লোহাগড়া | H18: 6266209 | I18: 6215591 | J18: =IFERROR(I18/H18%, 0) -> 99.192207 | K18: 0.0576 | L18: 0.0564 | M18: 0 | N18: 70 | O18: 69 | P18: =O18-N18 -> -1 | R18: 8 | S18: 9 | T18: =S18-R18 -> 1 | U18: 1
B19: মহাজন | G19: মহাজন | H19: 8188004 | I19: 8097309 | J19: =IFERROR(I19/H19%, 0) -> 98.892343 | K19: 0.0486 | L19: 0.0482 | M19: 0 | N19: 97 | O19: 97 | P19: =O19-N19 -> 0 | R19: 14 | S19: 10 | T19: =S19-R19 -> -4 | U19: 2
B20: গোবরা | G20: গোবরা | H20: 5743808 | I20: 5709346 | J20: =IFERROR(I20/H20%, 0) -> 99.400015 | K20: 0.0552 | L20: 0.0533 | M20: 1700 | N20: 119 | O20: 117 | P20: =O20-N20 -> -2 | Q20: 0 | R20: 6 | S20: 6 | T20: =S20-R20 -> 0 | U20: 0
B21: মোট | C21: =SUM(C16:C20) -> 0 | D21: =SUM(D16:D20) -> 0 | E21: =SUM(E16:E20) -> 0 | G21: মোট | H21: =SUM(H16:H20) -> 32554627 | I21: =SUM(I16:I20) -> 32272982 | J21: =AVERAGE(J16:J20) -> 99.158715 | K21: =AVERAGE(K16:K20) -> 0.05584 | L21: =IFERROR(AVERAGE(L16:L20), "") -> 0.05522 | M21: =SUM(M16:M20) -> 2266 | N21: =SUM(N16:N20) -> 518 | O21: =SUM(O16:O20) -> 515 | P21: =SUM(P16:P20) -> -3 | Q21: =SUM(Q16:Q20) -> 0 | R21: =SUM(R16:R20) -> 44 | S21: =SUM(S16:S20) -> 41 | T21: =SUM(T16:T20) -> -3 | U21: =SUM(U16:U20) -> 5
C22: হলুদ চিহ্নিত ঘরে সূত্র দেওয়া। হলুদ ঘরে লেখা যাবে না ।
J23: 31/08/26
B24: শাখা | C24: সংখ্যা | D24: Ex Recovery | F24: Overdue | J24: কল্যাণ তহবিল ফেরত | L24: ঋণ আদায় | O24: 31/8/26 ডিপিএস নতুন | R24: পূর্ণ ডিপিএস ফেরত | T24: সঞ্চয়
F25: শাখা | G25: গত মাস | H25: এ মাস | I25: হ্রাস /বৃদ্ধি | J25: সংখ্যা | K25: টাকা | L25: ঋণ | M25: সাঃচার্জ | O25: শাখা | P25: সংখ্যা | Q25: টাকা | R25: সংখ্যা | S25: টাকা | T25: আদায় | U25: ফেরত
B26: নড়াইল সদর | C26: 38 | D26: 45703 | F26: নড়াইল সদর | G26: 2733646 | H26: 2770418 | I26: =H26-G26 -> 36772 | J26: 1 | K26: 311425 | L26: 6530475 | M26: 1074874 | O26: নড়াইল সদর | P26: 16 | Q26: 11500 | R26: 0 | S26: 0 | T26: 1012084 | U26: 669585
B27: নলদী | C27: 35 | D27: 42386 | F27: নলদী | G27: 2844347 | H27: 2838342 | I27: =H27-G27 -> -6005 | J27: 1 | K27: 83331 | L27: 5918087 | M27: 855051 | O27: নলদী | P27: 22 | Q27: 15500 | R27: 1 | S27: 212620 | T27: 1146535 | U27: 840983
B28: লোহাগড়া | C28: 29 | D28: 36572 | F28: লোহাগড়া | G28: 2612631 | H28: 2632579 | I28: =H28-G28 -> 19948 | J28: 1 | K28: 74994 | L28: 6284607 | M28: 921613 | O28: লোহাগড়া | P28: 17 | Q28: 18500 | R28: 0 | S28: 0 | T28: 1406833 | U28: 1028509
B29: মহাজন | C29: 13 | D29: 54657 | F29: মহাজন | G29: 2563774 | H29: 2599812 | I29: =H29-G29 -> 36038 | J29: 1 | K29: 26299 | L29: 8287522 | M29: 1219912 | O29: মহাজন | P29: 17 | Q29: 17000 | R29: 0 | S29: 0 | T29: 1523668 | U29: 1113337
B30: গোবরা | C30: 32 | D30: 40080 | F30: গোবরা | G30: 2479055 | H30: 2473437 | I30: =H30-G30 -> -5618 | J30: 0 | K30: 0 | L30: 5775482 | M30: 896550 | O30: গোবরা | P30: 15 | Q30: 8500 | R30: 0 | S30: 0 | T30: 796421 | U30: 506897
B31: মোট | C31: =SUM(C26:C30) -> 147 | D31: =SUM(D26:D30) -> 219398 | F31: মোট | G31: =SUM(G26:G30) -> 13233453 | H31: =SUM(H26:H30) -> 13314588 | I31: =SUM(I26:I30) -> 81135 | J31: =SUM(J26:J30) -> 4 | K31: =SUM(K26:K30) -> 496049 | L31: =SUM(L26:L30) -> 32796173 | M31: =SUM(M26:M30) -> 4968000 | O31: মোট | P31: =SUM(P26:P30) -> 87 | Q31: =SUM(Q26:Q30) -> 71000 | R31: =SUM(R26:R30) -> 1 | S31: =SUM(S26:S30) -> 212620 | T31: =SUM(T26:T30) -> 5885541 | U31: =SUM(U26:U30) -> 4159311

Sheet Monthly Installment Recovery
A1: বন্ধু কল্যাণ ফাউন্ডেশন
A2: নড়াইল এরিয়া
A3: ফেব্রুয়ারী-২৩ মাসে বিতরনকৃত মাসিক অগ্রসর ঋণের আদায় তথ্য
A4: মাসের নামঃ- ফেব্রুয়ারী-২০২৩
A5: ক্রঃনং | B5: এরিয়ার নাম | C5: শাখার নাম | D5: নভেম্বর-২১ হতে-জানুয়ারী-২৩ পর্যন্ত মাসিক ঋণ বিতরন | H5: আদায় | R5: আদায় হার | S5: ডি,পি,এস
D6: ১ বছর | E6: ১৮ মাস | F6: ২ বছর | G6: মোট | H6: 44958 | I6: পার্থক্য | J6: =H6+1 -> 44959 | K6: পার্থক্য | L6: =J6+3 -> 44962 | M6: পার্থক্য | N6: =L6+1 -> 44963 | O6: পার্থক্য | P6: =N6+1 -> 44964 | Q6: পার্থক্য | S6: সংখ্যা | T6: টাকা
A7: ১ | B7: নড়াইল সদর
A8: ২ | B8: বাঘার পাড়া
A9: ৩ | B9: লোহাগড়া
A10: ৪ | B10: মহাজন
A11: ৫ | B11: নলদী
A12: ৬ | B12: গোবড়া
A13: মোট | D13: =SUM(D7:D12) -> 0 | E13: =SUM(E7:E12) -> 0 | F13: =SUM(F7:F12) -> 0 | G13: =SUM(G7:G12) -> 0 | H13: =SUM(H7:H12) -> 0 | J13: =SUM(J7:J12) -> 0 | L13: =SUM(L7:L12) -> 0 | N13: =SUM(N7:N12) -> 0 | P13: =SUM(P7:P12) -> 0 | R13: =SUM(R7:R12) -> 0 | S13: =SUM(S7:S12) -> 0 | T13: =SUM(T7:T12) -> 0
A15: বন্ধু কল্যাণ ফাউন্ডেশন
A16: নড়াইল এরিয়া
A17: =A3 -> ফেব্রুয়ারী-২৩ মাসে বিতরনকৃত মাসিক অগ্রসর ঋণের আদায় তথ্য
A18: =A4 -> মাসের নামঃ- ফেব্রুয়ারী-২০২৩
A19: ক্রঃনং | B19: এরিয়ার নাম | C19: শাখার নাম | D19: =D5 -> নভেম্বর-২১ হতে-জানুয়ারী-২৩ পর্যন্ত মাসিক ঋণ বিতরন | H19: আদায় | R19: আদায় হার | S19: ডি,পি,এস
D20: ১ বছর | E20: ১৮ মাস | F20: ২ বছর | G20: মোট | H20: =P6+1 -> 44965 | I20: পার্থক্য | J20: =H20+1 -> 44966 | K20: পার্থক্য | L20: =J20+3 -> 44969 | M20: পার্থক্য | N20: =L20+1 -> 44970 | O20: পার্থক্য | P20: =N20+1 -> 44971 | Q20: পার্থক্য | S20: সংখ্যা | T20: টাকা
A21: ১ | B21: নড়াইল সদর
A22: ২ | B22: বাঘার পাড়া
A23: ৩ | B23: লোহাগড়া
A24: ৪ | B24: মহাজন
A25: ৫ | B25: নলদী
A26: ৬ | B26: গোবড়া
A27: মোট | D27: =SUM(D21:D26) -> 0 | E27: =SUM(E21:E26) -> 0 | F27: =SUM(F21:F26) -> 0 | G27: =SUM(G21:G26) -> 0 | H27: =SUM(H21:H26) -> 0 | J27: =SUM(J21:J26) -> 0 | L27: =SUM(L21:L26) -> 0 | N27: =SUM(N21:N26) -> 0 | P27: =SUM(P21:P26) -> 0 | R27: =SUM(R21:R26) -> 0 | S27: =SUM(S21:S26) -> 0 | T27: =SUM(T21:T26) -> 0
A29: বন্ধু কল্যাণ ফাউন্ডেশন
A30: নড়াইল এরিয়া
A31: =A17 -> ফেব্রুয়ারী-২৩ মাসে বিতরনকৃত মাসিক অগ্রসর ঋণের আদায় তথ্য
A32: =A18 -> মাসের নামঃ- ফেব্রুয়ারী-২০২৩
A33: ক্রঃনং | B33: এরিয়ার নাম | C33: শাখার নাম | D33: =D19 -> নভেম্বর-২১ হতে-জানুয়ারী-২৩ পর্যন্ত মাসিক ঋণ বিতরন | H33: আদায় | R33: আদায় হার | S33: ডি,পি,এস
D34: ১ বছর | E34: ১৮ মাস | F34: ২ বছর | G34: মোট | H34: =P20+1 -> 44972 | I34: পার্থক্য | J34: =H34+1 -> 44973 | K34: পার্থক্য | L34: =J34+3 -> 44976 | M34: পার্থক্য | N34: =L34+1 -> 44977 | O34: পার্থক্য | P34: =N34+2 -> 44979 | Q34: পার্থক্য | S34: সংখ্যা | T34: টাকা
A35: ১ | B35: নড়াইল সদর
A36: ২ | B36: বাঘার পাড়া
A37: ৩ | B37: লোহাগড়া
A38: ৪ | B38: মহাজন
A39: ৫ | B39: নলদী
A40: ৬ | B40: গোবড়া
A41: মোট | D41: =SUM(D35:D40) -> 0 | E41: =SUM(E35:E40) -> 0 | F41: =SUM(F35:F40) -> 0 | G41: =SUM(G35:G40) -> 0 | H41: =SUM(H35:H40) -> 0 | J41: =SUM(J35:J40) -> 0 | L41: =SUM(L35:L40) -> 0 | N41: =SUM(N35:N40) -> 0 | P41: =SUM(P35:P40) -> 0 | R41: =SUM(R35:R40) -> 0 | S41: =SUM(S35:S40) -> 0 | T41: =SUM(T35:T40) -> 0
A43: বন্ধু কল্যাণ ফাউন্ডেশন
...

Sheet Monthly Total  Sumery
A1: Bandhu kallayan Foundation
A2: Rajghat,Abhaynagor, Jessore
A3: Date:
A4: SL | B4: Branch | C4: Member | E4: Lonee | G4: Reguler Terget (Loan) | H4: Reguler Achiv (Loan) | I4: Exced Over Due Collection | K4: Ad. Collection | L4: Over due De/Inc | M4: Recovary Rate
C5: Terget | D5: Achive | E5: Terget | F5: Achive | I5: Curent Due | J5: Ex Due
A6: 1 | B6: Narail Sodor | C6: =SUMIF('June-23'!$C:$C,$B$6:$B$11,'June-23'!D:D) -> #N/A | D6: =SUMIF('June-23'!$C:$C,$B$6:$B$11,'June-23'!E:E) -> #N/A | E6: =SUMIF('June-23'!$C:$C,$B$6:$B$11,'June-23'!G:G) -> #N/A | F6: =SUMIF('June-23'!$C:$C,$B$6:$B$11,'June-23'!H:H) -> #N/A | G6: =SUMIF('June-23'!$C:$C,$B$6:$B$11,'June-23'!M:M) -> #N/A | H6: =SUMIF('June-23'!$C:$C,$B$6:$B$11,'June-23'!N:N) -> #N/A | I6: =SUMIF('June-23'!$C:$C,$B$6:$B$11,'June-23'!O:O) -> #N/A | J6: =SUMIF('June-23'!$C:$C,$B$6:$B$11,'June-23'!P:P) -> #N/A | K6: =SUMIF('June-23'!$C:$C,$B$6:$B$11,'June-23'!Q:Q) -> #N/A | L6: =SUMIF('June-23'!$C:$C,$B$6:$B$11,'June-23'!R:R) -> #N/A | M6: =H6/G6 -> #N/A
A7: 2 | B7: Naldi | C7: =SUMIF('June-23'!$C:$C,$B$6:$B$11,'June-23'!D:D) -> #N/A | D7: =SUMIF('June-23'!$C:$C,$B$6:$B$11,'June-23'!E:E) -> #N/A | E7: =SUMIF('June-23'!$C:$C,$B$6:$B$11,'June-23'!G:G) -> #N/A | F7: =SUMIF('June-23'!$C:$C,$B$6:$B$11,'June-23'!H:H) -> #N/A | G7: =SUMIF('June-23'!$C:$C,$B$6:$B$11,'June-23'!M:M) -> #N/A | H7: =SUMIF('June-23'!$C:$C,$B$6:$B$11,'June-23'!N:N) -> #N/A | I7: =SUMIF('June-23'!$C:$C,$B$6:$B$11,'June-23'!O:O) -> #N/A | J7: =SUMIF('June-23'!$C:$C,$B$6:$B$11,'June-23'!P:P) -> #N/A | K7: =SUMIF('June-23'!$C:$C,$B$6:$B$11,'June-23'!Q:Q) -> #N/A | L7: =SUMIF('June-23'!$C:$C,$B$6:$B$11,'June-23'!R:R) -> #N/A | M7: =H7/G7 -> #N/A
A8: 3 | B8: Lohagora | C8: =SUMIF('June-23'!$C:$C,$B$6:$B$11,'June-23'!D:D) -> #N/A | D8: =SUMIF('June-23'!$C:$C,$B$6:$B$11,'June-23'!E:E) -> #N/A | E8: =SUMIF('June-23'!$C:$C,$B$6:$B$11,'June-23'!G:G) -> #N/A | F8: =SUMIF('June-23'!$C:$C,$B$6:$B$11,'June-23'!H:H) -> #N/A | G8: =SUMIF('June-23'!$C:$C,$B$6:$B$11,'June-23'!M:M) -> #N/A | H8: =SUMIF('June-23'!$C:$C,$B$6:$B$11,'June-23'!N:N) -> #N/A | I8: =SUMIF('June-23'!$C:$C,$B$6:$B$11,'June-23'!O:O) -> #N/A | J8: =SUMIF('June-23'!$C:$C,$B$6:$B$11,'June-23'!P:P) -> #N/A | K8: =SUMIF('June-23'!$C:$C,$B$6:$B$11,'June-23'!Q:Q) -> #N/A | L8: =SUMIF('June-23'!$C:$C,$B$6:$B$11,'June-23'!R:R) -> #N/A | M8: =H8/G8 -> #N/A
A9: 4 | B9: Mohajon | C9: =SUMIF('June-23'!$C:$C,$B$6:$B$11,'June-23'!D:D) -> #N/A | D9: =SUMIF('June-23'!$C:$C,$B$6:$B$11,'June-23'!E:E) -> #N/A | E9: =SUMIF('June-23'!$C:$C,$B$6:$B$11,'June-23'!G:G) -> #N/A | F9: =SUMIF('June-23'!$C:$C,$B$6:$B$11,'June-23'!H:H) -> #N/A | G9: =SUMIF('June-23'!$C:$C,$B$6:$B$11,'June-23'!M:M) -> #N/A | H9: =SUMIF('June-23'!$C:$C,$B$6:$B$11,'June-23'!N:N) -> #N/A | I9: =SUMIF('June-23'!$C:$C,$B$6:$B$11,'June-23'!O:O) -> #N/A | J9: =SUMIF('June-23'!$C:$C,$B$6:$B$11,'June-23'!P:P) -> #N/A | K9: =SUMIF('June-23'!$C:$C,$B$6:$B$11,'June-23'!Q:Q) -> #N/A | L9: =SUMIF('June-23'!$C:$C,$B$6:$B$11,'June-23'!R:R) -> #N/A | M9: =H9/G9 -> #N/A
A10: 5 | B10: Gobra | C10: =SUMIF('June-23'!$C:$C,$B$6:$B$11,'June-23'!D:D) -> #N/A | D10: =SUMIF('June-23'!$C:$C,$B$6:$B$11,'June-23'!E:E) -> #N/A | E10: =SUMIF('June-23'!$C:$C,$B$6:$B$11,'June-23'!G:G) -> #N/A | F10: =SUMIF('June-23'!$C:$C,$B$6:$B$11,'June-23'!H:H) -> #N/A | G10: =SUMIF('June-23'!$C:$C,$B$6:$B$11,'June-23'!M:M) -> #N/A | H10: =SUMIF('June-23'!$C:$C,$B$6:$B$11,'June-23'!N:N) -> #N/A | I10: =SUMIF('June-23'!$C:$C,$B$6:$B$11,'June-23'!O:O) -> #N/A | J10: =SUMIF('June-23'!$C:$C,$B$6:$B$11,'June-23'!P:P) -> #N/A | K10: =SUMIF('June-23'!$C:$C,$B$6:$B$11,'June-23'!Q:Q) -> #N/A | L10: =SUMIF('June-23'!$C:$C,$B$6:$B$11,'June-23'!R:R) -> #N/A | M10: =H10/G10 -> #N/A
A11: 6 | B11: Bagharpara | C11: =SUMIF('June-23'!$C:$C,$B$6:$B$11,'June-23'!D:D) -> #N/A | D11: =SUMIF('June-23'!$C:$C,$B$6:$B$11,'June-23'!E:E) -> #N/A | E11: =SUMIF('June-23'!$C:$C,$B$6:$B$11,'June-23'!G:G) -> #N/A | F11: =SUMIF('June-23'!$C:$C,$B$6:$B$11,'June-23'!H:H) -> #N/A | G11: =SUMIF('June-23'!$C:$C,$B$6:$B$11,'June-23'!M:M) -> #N/A | H11: =SUMIF('June-23'!$C:$C,$B$6:$B$11,'June-23'!N:N) -> #N/A | I11: =SUMIF('June-23'!$C:$C,$B$6:$B$11,'June-23'!O:O) -> #N/A | J11: =SUMIF('June-23'!$C:$C,$B$6:$B$11,'June-23'!P:P) -> #N/A | K11: =SUMIF('June-23'!$C:$C,$B$6:$B$11,'June-23'!Q:Q) -> #N/A | L11: =SUMIF('June-23'!$C:$C,$B$6:$B$11,'June-23'!R:R) -> #N/A | M11: =H11/G11 -> #N/A
A12: Total | C12: =SUM(C6:C11) -> #N/A | D12: =SUM(D6:D11) -> #N/A | E12: =SUM(E6:E11) -> #N/A | F12: =SUM(F6:F11) -> #N/A | G12: =SUM(G6:G11) -> #N/A | H12: =SUM(H6:H11) -> #N/A | I12: =SUM(I6:I11) -> #N/A | J12: =SUM(J6:J11) -> #N/A | ... L12: =SUM(L6:L11) -> #N/A | M12: =H12/G12 -> #N/A

Sheet Month Closing-July-26
A44: বন্ধু কল্যাণ ফাউন্ডেশন
A46: শাখা ভিত্তিক মাসিক অ্যাচিভমেন্ট সিট
A47: মাসের নাম- জুন-২০২৬ | M47: নড়াইল এরিয়া | Z47: ZvwiL =30/12/25
A48: ক্র নং | B48: শাখার নাম | C48: সমিতি | D48: সদস্য | F48: ঋণী | H48: সঞ্চয় স্থিতি | J48: ঋণ স্থিতি | L48: সাধারণ বকেয়া | N48: OTR | P48: হ্রাস /বৃদ্ধি | Q48: হাতে নগদ | R48: ব্যাংক | S48: লাভ/ক্ষতি | V48: বিতরণ- জুন-২৬
D49: হ্রাস /বৃদ্ধি | E49: মোট | F49: হ্রাস /বৃদ্ধি | G49: মোট | H49: হ্রাস /বৃদ্ধি | I49: মোট | J49: হ্রাস /বৃদ্ধি | K49: মোট | L49: হ্রাস /বৃদ্ধি | M49: মোট | N49: বিগত মাস | O49: এ মাস | S49: এ মাসে | T49: এ বছর | U49: এ যাবৎ | V49: সংখ্যা | W49: টাকা
A50: 1 | B50: নড়াইল সদর | C50: 58 | D50: -94 | E50: 832 | F50: -4 | G50: 696 | H50: 845055 | I50: 16872121 | J50: 282700 | K50: 59470091 | L50: 42539 | M50: 2685411 | N50: 98.44 | O50: 98.69 | P50: =O50-N50 -> 0.25 | Q50: 50890 | R50: 769229 | S50: -136199 | T50: 667340 | U50: 3296495 | V50: 49 | W50: 6720000
A51: 2 | B51: নলদী | C51: 63 | D51: -99 | E51: 851 | F51: 10 | G51: 692 | H51: 806639 | I51: 15617974 | J51: 1593716 | K51: 51081813 | L51: -15077 | M51: 2867330 | N51: 99.01 | O51: 99.64 | P51: =O51-N51 -> 0.63 | Q51: 28 | R51: 414828 | S51: 142382 | T51: 2021237 | U51: 8911723 | V51: 58 | W51: 7375000
A52: 3 | B52: লোহাগড়া | C52: 69 | D52: -27 | E52: 767 | F52: =7 -> 7 | G52: 649 | H52: 1234353 | I52: 18618343 | J52: 1393639 | K52: 52128856 | L52: 24483 | M52: 2588821 | N52: 99.05 | O52: =J62/I62% -> 99.059702 | P52: =O52-N52 -> 0.009702376 | Q52: 785 | R52: 562448 | S52: 68297 | T52: 2077801 | U52: 10389492 | V52: 49 | W52: 7360000
A53: 4 | B53: মহাজন | C53: 60 | D53: -102 | E53: 897 | F53: -8 | G53: 767 | H53: 852505 | I53: 21964653 | J53: 2504987 | K53: 67718940 | L53: -420 | M53: 2536589 | N53: 98.91 | O53: 99.04 | P53: =O53-N53 -> 0.13 | Q53: 42505 | R53: 484299 | S53: 80858 | T53: 2501540 | U53: 4156703 | V53: 62 | W53: 10125000
A54: 5 | B54: গোবরা | C54: 72 | D54: =Helper!B3-Helper!A3 -> 4 | E54: =Helper!B3 -> 897 | F54: 8 | G54: 747 | H54: =Helper!F3-Helper!E3 -> 289524 | I54: =Helper!F3 -> 16266960 | J54: 1233996 | K54: 50558020 | L54: -40662 | M54: 2481193 | N54: =4947896/4983008*100 -> 99.295365 | O54: =J64/I64% -> 99.145194 | P54: =O54-N54 -> -0.15017173 | Q54: 66407 | R54: 1361296 | S54: 243934 | T54: 2776874 | U54: 16830905 | V54: 62 | W54: 6946000
B55: মোট | C55: =SUM(C50:C54) -> 322 | D55: =SUM(D50:D54) -> -318 | E55: =SUM(E50:E54) -> 4244 | F55: =SUM(F50:F54) -> 13 | G55: =SUM(G50:G54) -> 3551 | H55: =SUM(H50:H54) -> 4028076 | I55: =SUM(I50:I54) -> 89340051 | J55: =SUM(J50:J54) -> 7009038 | ... M55: =SUM(M50:M54) -> 13159344 | N55: =AVERAGE(N50:N54) -> 98.941073 | O55: =AVERAGE(O50:O54) -> 99.114979 | P55: =SUM(P50:P54) -> 0.86953065 | Q55: =SUM(Q50:Q54) -> 160615 | R55: =SUM(R50:R54) -> 3592100 | S55: =SUM(S50:S54) -> 399272 | T55: =SUM(T50:T54) -> 10044792 | U55: =SUM(U50:U54) -> 43585318 | V55: =SUM(V50:V54) -> 280 | W55: =SUM(W50:W54) -> 38526000
A56: হলুদ চিহ্নিত ঘরে সূত্র দেওয়া। হলুদ ঘরে লেখা যাবে না ।
B58: শাখা | C58: সংখ্যা | D58: সঞ্চয় লভ্যাংশ | E58: মাসিক কিস্তির সংখ্যা | H58: শাখা | I58: আদায়যোগ্য | J58: আদায়কৃত | K58: OTR | L58: বিগত পার | M58: এ মাসে পার | N58: রাইট অফ আদায় | O58: বকেয়া গত মাস | P58: বকেয়া এ মাস | Q58: হ্রাস /বৃদ্ধি | R58: LLP | S58: চলতি বকেয়া | U58: হ্রাস /বৃদ্ধি | V58: এ মাসে নতুন
S59: গত মাস | T59: বর্তমান মাস
B60: নড়াইল সদর | C60: 832 | D60: 649476 | H60: নড়াইল সদর | I60: 6411950 | J60: 6327753 | K60: =O50 -> 98.69 | L60: 6.66 | M60: 0.0615 | N60: 150 | O60: 99 | P60: 92 | Q60: =P60-O60 -> -7 | R60: 350016 | S60: 15 | T60: 12 | U60: =T60-S60 -> -3 | V60: 0
B61: নলদী | C61: 851 | D61: 496253 | H61: নলদী | I61: 5687784 | J61: 5667114 | K61: =O51 -> 99.64 | L61: 6.33 | M61: 0.0601 | N61: 0 | O61: 145 | P61: 141 | Q61: =P61-O61 -> -4 | R61: 128618 | S61: 3 | T61: 3 | U61: =T61-S61 -> 0 | V61: 0
B62: লোহাগড়া | C62: 767 | D62: 614713 | H62: লোহাগড়া | I62: 5963431 | J62: 5907357 | K62: =O52 -> 99.059702 | L62: 6.34 | M62: 0.0612 | N62: 251 | O62: 71 | P62: 72 | Q62: =P62-O62 -> 1 | R62: 228292 | S62: 8 | T62: 9 | U62: =T62-S62 -> 1 | V62: 1
B63: মহাজন | C63: 897 | D63: 730207 | H63: মহাজন | I63: 7546472 | J63: 7474024 | K63: =O53 -> 99.04 | L63: 4.78 | M63: 0.0455 | N63: 3305 | O63: 98 | P63: 95 | Q63: =P63-O63 -> -3 | R63: 270652 | S63: 13 | T63: 12 | U63: =T63-S63 -> -1 | V63: 2
B64: গোবরা | C64: 891 | D64: 551285 | E64: 430 | H64: গোবরা | I64: 5541138 | J64: 5493772 | K64: =O54 -> 99.145194 | L64: 6.23 | M64: 0.0582 | N64: 750 | O64: 120 | P64: 120 | Q64: =P64-O64 -> 0 | R64: 131412 | S64: 8 | T64: 8 | U64: =T64-S64 -> 0 | V64: 2
B65: মোট | C65: =SUM(C60:C64) -> 4238 | D65: =SUM(D60:D64) -> 3041934 | E65: =SUM(E60:E64) -> 430 | H65: মোট | I65: =SUM(I60:I64) -> 31150775 | J65: =SUM(J60:J64) -> 30870020 | K65: =AVERAGE(K60:K64) -> 99.114979 | L65: =AVERAGE(L60:L64) -> 6.068 | M65: =AVERAGE(M60:M64) -> 0.0573 | N65: =SUM(N60:N64) -> 4456 | O65: =SUM(O60:O64) -> 533 | P65: =SUM(P60:P64) -> 520 | Q65: =SUM(Q60:Q64) -> -13 | R65: =SUM(R60:R64) -> 1108990 | S65: =SUM(S60:S64) -> 47 | T65: =SUM(T60:T64) -> 44 | U65: =SUM(U60:U64) -> -3 | V65: =SUM(V60:V64) -> 5
A66: হলুদ চিহ্নিত ঘরে সূত্র দেওয়া। হলুদ ঘরে লেখা যাবে না ।
H67: এ মাস | J67: 30/06/26
B68: শাখা | C68: সংখ্যা | D68: Ex Recovery | H68: Overdue | L68: কল্যাণ তহবিল ফেরত | N68: ঋণ আদায় | Q68: 30/6/26 ডিপিএস নতুন | U68: সঞ্চয়
H69: শাখা | I69: গত মাস | J69: এ মাস | K69: হ্রাস /বৃদ্ধি | L69: সংখ্যা | M69: টাকা | N69: ঋণ | O69: সাঃচার্জ | Q69: শাখা | R69: সংখ্যা | S69: টাকা | T69: পূর্ণ ডিপিএস ফেরত | U69: আদায় | V69: ফেরত
B70: নড়াইল সদর | C70: 57 | D70: 51007 | H70: নড়াইল সদর | I70: 2642872 | J70: 2685411 | K70: =J70-I70 -> 42539 | L70: 1 | M70: 25530 | N70: 6437300 | O70: 1101877 | Q70: নড়াইল সদর | R70: 28 | S70: 14800 | U70: 1102471 | V70: 906892
B71: নলদী | C71: 82 | D71: 35747 | H71: নলদী | I71: 2882407 | J71: 2867330 | K71: =J71-I71 -> -15077 | L71: 0 | M71: 0 | N71: 5781284 | O71: 838051 | Q71: নলদী | R71: 19 | S71: 11500 | T71: 0 | U71: 1134387 | V71: 824001
B72: লোহাগড়া | C72: 39 | D72: 36368 | H72: লোহাগড়া | I72: 2564338 | J72: 2588821 | K72: =J72-I72 -> 24483 | L72: 1 | M72: 66664 | N72: 5966361 | O72: 870005 | Q72: লোহাগড়া | R72: 27 | S72: 27000 | T72: 0 | U72: 1434071 | V72: 814431
B73: মহাজন | C73: 30 | D73: 72868 | H73: মহাজন | I73: 2537009 | J73: 2536589 | K73: =J73-I73 -> -420 | L73: 1 | M73: 1854 | N73: 7620013 | O73: 1158624 | Q73: মহাজন | R73: 22 | S73: 30500 | T73: 1/106310 | U73: 1492868 | V73: 1370570
B74: গোবরা | C74: 93 | D74: 88028 | H74: গোবরা | I74: 2521855 | J74: =M54 -> 2481193 | K74: =J74-I74 -> -40662 | L74: 0 | M74: 0 | N74: 5712004 | O74: 889169 | Q74: গোবরা | R74: 15 | S74: 9000 | T74: 0 | U74: 893537 | V74: 460857
B75: মোট | C75: =SUM(C70:C74) -> 301 | D75: =SUM(D70:D74) -> 284018 | H75: মোট | I75: =SUM(I70:I74) -> 13148481 | J75: =SUM(J70:J74) -> 13159344 | K75: =SUM(K70:K74) -> 10863 | L75: =SUM(L70:L74) -> 3 | M75: =SUM(M70:M74) -> 94048 | N75: =SUM(N70:N74) -> 31516962 | O75: =SUM(O70:O74) -> 4857726 | Q75: মোট | R75: =SUM(R70:R74) -> 111 | S75: =SUM(S70:S74) -> 92800 | T75: 1/106310 | U75: =SUM(U70:U74) -> 6057334 | V75: =SUM(V70:V74) -> 4376751

Sheet Budget
A1: Bandhu Kallayn Foundation
A2: Branch Name: | B2: Narail Sador | I2: Budget 2022-2023
A3: Description | B3: Outstanding- Jun-26 | C3: 46210 | D3: 46260 | E3: 46291 | F3: 46321 | G3: 46352 | H3: 46382 | I3: 46048 | J3: 46079 | K3: 46107 | L3: 46138 | M3: 46168 | N3: 46199 | O3: Total | P3: End Outstanding
A4: Member | O4: =SUM(C4:L4) -> 0 | P4: =B4+O4 -> 0
A5: Lonee | O5: =SUM(C5:L5) -> 0 | P5: =B5+O5 -> 0
A6: Savings | O6: =SUM(C6:L6) -> 0 | P6: =B6+O6 -> 0
A7: Loan | O7: =SUM(C7:L7) -> 0 | P7: =B7+O7 -> 0
A8: Over Due | O8: =SUM(C8:L8) -> 0 | P8: =B8+O8 -> 0
A10: Bandhu Kallayn Foundation
A11: Branch Name: | B11: Naldi | I11: Budget 2022-2023
A12: Description | B12: Outstanding- Jun-26 | C12: 46210 | D12: 46260 | E12: 46291 | F12: 46321 | G12: 46352 | H12: 46382 | I12: 46048 | J12: 46079 | K12: 46107 | L12: 46138 | M12: 46168 | N12: 46199 | O12: Total | P12: End Outstanding
A13: Member | O13: =SUM(C13:L13) -> 0 | P13: =B13+O13 -> 0
A14: Lonee | O14: =SUM(C14:L14) -> 0 | P14: =B14+O14 -> 0
A15: Savings | O15: =SUM(C15:L15) -> 0 | P15: =B15+O15 -> 0
A16: Loan | O16: =SUM(C16:L16) -> 0 | P16: =B16+O16 -> 0
A17: Over Due | O17: =SUM(C17:L17) -> 0 | P17: =B17+O17 -> 0
A19: Bandhu Kallayn Foundation
A20: Branch Name: | B20: Lohagora | I20: Budget 2022-2023
A21: Description | B21: Outstanding- Jun-26 | C21: 46210 | D21: 46260 | E21: 46291 | F21: 46321 | G21: 46352 | H21: 46382 | I21: 46048 | J21: 46079 | K21: 46107 | L21: 46138 | M21: 46168 | N21: 46199 | O21: Total | P21: End Outstanding
A22: Member | O22: =SUM(C22:L22) -> 0 | P22: =B22+O22 -> 0
A23: Lonee | O23: =SUM(C23:L23) -> 0 | P23: =B23+O23 -> 0
A24: Savings | O24: =SUM(C24:L24) -> 0 | P24: =B24+O24 -> 0
A25: Loan | O25: =SUM(C25:L25) -> 0 | P25: =B25+O25 -> 0
A26: Over Due | O26: =SUM(C26:L26) -> 0 | P26: =B26+O26 -> 0
A28: Bandhu Kallayn Foundation
A29: Branch Name: | B29: Mahajon | I29: Budget 2022-2023
A30: Description | B30: Outstanding- Jun-26 | C30: 46210 | D30: 46260 | E30: 46291 | F30: 46321 | G30: 46352 | H30: 46382 | I30: 46048 | J30: 46079 | K30: 46107 | L30: 46138 | M30: 46168 | N30: 46199 | O30: Total | P30: End Outstanding
A31: Member | O31: =SUM(C31:L31) -> 0 | P31: =B31+O31 -> 0
A32: Lonee | O32: =SUM(C32:L32) -> 0 | P32: =B32+O32 -> 0
A33: Savings | O33: =SUM(C33:L33) -> 0 | P33: =B33+O33 -> 0
A34: Loan | O34: =SUM(C34:L34) -> 0 | P34: =B34+O34 -> 0
A35: Over Due | O35: =SUM(C35:L35) -> 0 | P35: =B35+O35 -> 0
A37: Bandhu Kallayn Foundation
A38: Branch Name: | B38: Narail Sador | I38: Budget 2022-2023
A39: Description | B39: Outstanding- Jun-26 | C39: 46210 | D39: 46260 | E39: 46291 | F39: 46321 | G39: 46352 | H39: 46382 | I39: 46048 | J39: 46079 | K39: 46107 | L39: 46138 | M39: 46168 | N39: 46199 | O39: Total | P39: End Outstanding
A40: Member | O40: =SUM(C40:L40) -> 0 | P40: =B40+O40 -> 0
A41: Lonee | O41: =SUM(C41:L41) -> 0 | P41: =B41+O41 -> 0
A42: Savings | O42: =SUM(C42:L42) -> 0 | P42: =B42+O42 -> 0
A43: Loan | O43: =SUM(C43:L43) -> 0 | P43: =B43+O43 -> 0
A44: Over Due | O44: =SUM(C44:L44) -> 0 | P44: =B44+O44 -> 0
...

Sheet Helper
A1: Member | C1: Lonee | E1: Savings | G1: Loan | I1: Overdue
A2: Upto | B2: This Month | C2: Upto | D2: This Month | E2: Upto | F2: This Month | G2: Upto | H2: This Month | I2: Upto | J2: This Month
A3: 893 | B3: 897 | C3: 747 | D3: 741 | E3: 15977436 | F3: 16266960 | G3: 51484373 | H3: 51988891 | I3: 2479055 | J3: 2473437
